Traceback (most recent call last):
  File "C:\Users\pamcl\WPy64-31230\python-3.12.3.amd64\Lib\site-packages\jupyter_cache\executors\utils.py", line 58, in single_nb_execution
    executenb(
  File "C:\Users\pamcl\WPy64-31230\python-3.12.3.amd64\Lib\site-packages\nbclient\client.py", line 1314, in execute
    return NotebookClient(nb=nb, resources=resources, km=km, **kwargs).execute()
           ^^^^^^^^^^^^^^^^^^^^^^^^^^^^^^^^^^^^^^^^^^^^^^^^^^^^^^^^^^^^^^^^^^^^^
  File "C:\Users\pamcl\WPy64-31230\python-3.12.3.amd64\Lib\site-packages\jupyter_core\utils\__init__.py", line 173, in wrapped
    return loop.run_until_complete(inner)
           ^^^^^^^^^^^^^^^^^^^^^^^^^^^^^^
  File "C:\Users\pamcl\WPy64-31230\python-3.12.3.amd64\Lib\asyncio\base_events.py", line 687, in run_until_complete
    return future.result()
           ^^^^^^^^^^^^^^^
  File "C:\Users\pamcl\WPy64-31230\python-3.12.3.amd64\Lib\site-packages\nbclient\client.py", line 709, in async_execute
    await self.async_execute_cell(
  File "C:\Users\pamcl\WPy64-31230\python-3.12.3.amd64\Lib\site-packages\nbclient\client.py", line 1062, in async_execute_cell
    await self._check_raise_for_error(cell, cell_index, exec_reply)
  File "C:\Users\pamcl\WPy64-31230\python-3.12.3.amd64\Lib\site-packages\nbclient\client.py", line 918, in _check_raise_for_error
    raise CellExecutionError.from_cell_and_msg(cell, exec_reply_content)
nbclient.exceptions.CellExecutionError: An error occurred while executing the following cell:
------------------
import importlib.util
 
# specify the module that needs to be 
# imported relative to the path of the 
# module
spec=importlib.util.spec_from_file_location("edcrop", r"C:\Users\au701230\WPy64-31090\python-3.10.9.amd64\Lib\site-packages\edcrop\edcrop.py")
 
# creates a new module based on spec
foo = importlib.util.module_from_spec(spec)
 
# executes the module in its own namespace
# when a module is imported or reloaded.
spec.loader.exec_module(foo)

import os
import pandas as pd
import matplotlib.pyplot as plt
import warnings
warnings.simplefilter(action='ignore', category=FutureWarning)

wdir = os.path.join(os.getcwd())

os.chdir(wdir)

yaml = os.path.join(wdir, 'yaml_files/wetland.yaml')

foo.run_model(yaml=yaml)

------------------


[1;31m---------------------------------------------------------------------------[0m
[1;31mFileNotFoundError[0m                         Traceback (most recent call last)
Cell [1;32mIn[1], line 13[0m
[0;32m      9[0m foo [38;5;241m=[39m importlib[38;5;241m.[39mutil[38;5;241m.[39mmodule_from_spec(spec)
[0;32m     11[0m [38;5;66;03m# executes the module in its own namespace[39;00m
[0;32m     12[0m [38;5;66;03m# when a module is imported or reloaded.[39;00m
[1;32m---> 13[0m [43mspec[49m[38;5;241;43m.[39;49m[43mloader[49m[38;5;241;43m.[39;49m[43mexec_module[49m[43m([49m[43mfoo[49m[43m)[49m
[0;32m     15[0m [38;5;28;01mimport[39;00m [38;5;21;01mos[39;00m
[0;32m     16[0m [38;5;28;01mimport[39;00m [38;5;21;01mpandas[39;00m [38;5;28;01mas[39;00m [38;5;21;01mpd[39;00m

File [1;32m<frozen importlib._bootstrap_external>:991[0m, in [0;36mexec_module[1;34m(self, module)[0m

File [1;32m<frozen importlib._bootstrap_external>:1128[0m, in [0;36mget_code[1;34m(self, fullname)[0m

File [1;32m<frozen importlib._bootstrap_external>:1186[0m, in [0;36mget_data[1;34m(self, path)[0m

[1;31mFileNotFoundError[0m: [Errno 2] No such file or directory: 'C:\\Users\\au701230\\WPy64-31090\\python-3.10.9.amd64\\Lib\\site-packages\\edcrop\\edcrop.py'

